Traceback (most recent call last):
  File "/opt/homebrew/lib/python3.9/site-packages/jupyter_cache/executors/utils.py", line 58, in single_nb_execution
    executenb(
  File "/Users/leena/Library/Python/3.9/lib/python/site-packages/nbclient/client.py", line 1265, in execute
    return NotebookClient(nb=nb, resources=resources, km=km, **kwargs).execute()
  File "/Users/leena/Library/Python/3.9/lib/python/site-packages/jupyter_core/utils/__init__.py", line 166, in wrapped
    return loop.run_until_complete(inner)
  File "/opt/homebrew/Cellar/python@3.9/3.9.19/Frameworks/Python.framework/Versions/3.9/lib/python3.9/asyncio/base_events.py", line 647, in run_until_complete
    return future.result()
  File "/Users/leena/Library/Python/3.9/lib/python/site-packages/nbclient/client.py", line 703, in async_execute
    await self.async_execute_cell(
  File "/Users/leena/Library/Python/3.9/lib/python/site-packages/nbclient/client.py", line 1021, in async_execute_cell
    await self._check_raise_for_error(cell, cell_index, exec_reply)
  File "/Users/leena/Library/Python/3.9/lib/python/site-packages/nbclient/client.py", line 915, in _check_raise_for_error
    raise CellExecutionError.from_cell_and_msg(cell, exec_reply_content)
nbclient.exceptions.CellExecutionError: An error occurred while executing the following cell:
------------------
import openmdao.api as om

prob = om.Problem(model=SellarMDA())
prob.setup(check=False, mode='rev')

prob.driver = om.pyOptSparseDriver(optimizer='SLSQP')

prob.run_driver()
------------------

[0;31m---------------------------------------------------------------------------[0m
[0;31mRuntimeError[0m                              Traceback (most recent call last)
Cell [0;32mIn[5], line 6[0m
[1;32m      3[0m prob [38;5;241m=[39m om[38;5;241m.[39mProblem(model[38;5;241m=[39mSellarMDA())
[1;32m      4[0m prob[38;5;241m.[39msetup(check[38;5;241m=[39m[38;5;28;01mFalse[39;00m, mode[38;5;241m=[39m[38;5;124m'[39m[38;5;124mrev[39m[38;5;124m'[39m)
[0;32m----> 6[0m prob[38;5;241m.[39mdriver [38;5;241m=[39m [43mom[49m[38;5;241;43m.[39;49m[43mpyOptSparseDriver[49m[43m([49m[43moptimizer[49m[38;5;241;43m=[39;49m[38;5;124;43m'[39;49m[38;5;124;43mSLSQP[39;49m[38;5;124;43m'[39;49m[43m)[49m
[1;32m      8[0m prob[38;5;241m.[39mrun_driver()

File [0;32m~/dev/eecs481/hw6/OpenMDAO/openmdao/drivers/pyoptsparse_driver.py:198[0m, in [0;36mpyOptSparseDriver.__init__[0;34m(self, **kwargs)[0m
[1;32m    193[0m [38;5;250m[39m[38;5;124;03m"""[39;00m
[1;32m    194[0m [38;5;124;03mInitialize pyopt.[39;00m
[1;32m    195[0m [38;5;124;03m"""[39;00m
[1;32m    196[0m [38;5;28;01mif[39;00m pyoptsparse [38;5;129;01mis[39;00m [38;5;28;01mNone[39;00m:
[1;32m    197[0m     [38;5;66;03m# pyoptsparse is not installed[39;00m
[0;32m--> 198[0m     [38;5;28;01mraise[39;00m [38;5;167;01mRuntimeError[39;00m([38;5;124m'[39m[38;5;124mpyOptSparseDriver is not available, pyOptsparse is not installed.[39m[38;5;124m'[39m)
[1;32m    200[0m [38;5;28;01mif[39;00m [38;5;28misinstance[39m(pyoptsparse, [38;5;167;01mException[39;00m):
[1;32m    201[0m     [38;5;66;03m# there is some other issue with the pyoptsparse installation[39;00m
[1;32m    202[0m     [38;5;28;01mraise[39;00m pyoptsparse

[0;31mRuntimeError[0m: pyOptSparseDriver is not available, pyOptsparse is not installed.
RuntimeError: pyOptSparseDriver is not available, pyOptsparse is not installed.

